Traceback (most recent call last):
<<<<<<< HEAD
  File "C:\ProgramData\Miniconda3\envs\mem680\lib\site-packages\nbclient\client.py", line 778, in _async_poll_for_reply
    msg = await ensure_async(self.kc.shell_channel.get_msg(timeout=new_timeout))
  File "C:\ProgramData\Miniconda3\envs\mem680\lib\site-packages\jupyter_core\utils\__init__.py", line 189, in ensure_async
    result = await obj
  File "C:\ProgramData\Miniconda3\envs\mem680\lib\site-packages\jupyter_client\channels.py", line 315, in get_msg
    raise Empty
_queue.Empty

During handling of the above exception, another exception occurred:

Traceback (most recent call last):
  File "C:\ProgramData\Miniconda3\envs\mem680\lib\site-packages\jupyter_cache\executors\utils.py", line 58, in single_nb_execution
    executenb(
  File "C:\ProgramData\Miniconda3\envs\mem680\lib\site-packages\nbclient\client.py", line 1305, in execute
    return NotebookClient(nb=nb, resources=resources, km=km, **kwargs).execute()
  File "C:\ProgramData\Miniconda3\envs\mem680\lib\site-packages\jupyter_core\utils\__init__.py", line 173, in wrapped
    return loop.run_until_complete(inner)
  File "C:\ProgramData\Miniconda3\envs\mem680\lib\asyncio\base_events.py", line 641, in run_until_complete
    return future.result()
  File "C:\ProgramData\Miniconda3\envs\mem680\lib\site-packages\nbclient\client.py", line 705, in async_execute
    await self.async_execute_cell(
  File "C:\ProgramData\Miniconda3\envs\mem680\lib\site-packages\nbclient\client.py", line 1001, in async_execute_cell
    exec_reply = await self.task_poll_for_reply
  File "C:\ProgramData\Miniconda3\envs\mem680\lib\site-packages\nbclient\client.py", line 802, in _async_poll_for_reply
    error_on_timeout_execute_reply = await self._async_handle_timeout(timeout, cell)
  File "C:\ProgramData\Miniconda3\envs\mem680\lib\site-packages\nbclient\client.py", line 852, in _async_handle_timeout
    raise CellTimeoutError.error_from_timeout_and_cell(
nbclient.exceptions.CellTimeoutError: A cell timed out while it was being executed, after 600 seconds.
The message was: Cell execution timed out.
Here is a preview of the cell contents:
-------------------
diff(sin(x) * exp(x), x)

-------------------
=======
  File "C:\Conda\envs\mem680\lib\site-packages\jupyter_cache\executors\utils.py", line 58, in single_nb_execution
    executenb(
  File "C:\Users\Joshua Agar\AppData\Roaming\Python\Python310\site-packages\nbclient\client.py", line 1263, in execute
    return NotebookClient(nb=nb, resources=resources, km=km, **kwargs).execute()
  File "C:\Users\Joshua Agar\AppData\Roaming\Python\Python310\site-packages\nbclient\util.py", line 85, in wrapped
    return just_run(coro(*args, **kwargs))
  File "C:\Users\Joshua Agar\AppData\Roaming\Python\Python310\site-packages\nbclient\util.py", line 60, in just_run
    return loop.run_until_complete(coro)
  File "C:\Conda\envs\mem680\lib\asyncio\base_events.py", line 649, in run_until_complete
    return future.result()
  File "C:\Users\Joshua Agar\AppData\Roaming\Python\Python310\site-packages\nbclient\client.py", line 701, in async_execute
    await self.async_execute_cell(
  File "C:\Users\Joshua Agar\AppData\Roaming\Python\Python310\site-packages\nbclient\client.py", line 1019, in async_execute_cell
    await self._check_raise_for_error(cell, cell_index, exec_reply)
  File "C:\Users\Joshua Agar\AppData\Roaming\Python\Python310\site-packages\nbclient\client.py", line 913, in _check_raise_for_error
    raise CellExecutionError.from_cell_and_msg(cell, exec_reply_content)
nbclient.exceptions.CellExecutionError: An error occurred while executing the following cell:
------------------
import sympy

sympy.sqrt(8)
------------------

[1;31m---------------------------------------------------------------------------[0m
[1;31mModuleNotFoundError[0m                       Traceback (most recent call last)
Cell [1;32mIn [3], line 1[0m
[1;32m----> 1[0m [38;5;28;01mimport[39;00m [38;5;21;01msympy[39;00m
[0;32m      3[0m sympy[38;5;241m.[39msqrt([38;5;241m8[39m)

[1;31mModuleNotFoundError[0m: No module named 'sympy'
ModuleNotFoundError: No module named 'sympy'
>>>>>>> 6705a020b0958f423ff6ce78f503bc970904e6d0

