Traceback (most recent call last):
  File "C:\Users\jca92\.conda\envs\mem680\lib\site-packages\jupyter_cache\executors\utils.py", line 58, in single_nb_execution
    executenb(
  File "C:\Users\jca92\.conda\envs\mem680\lib\site-packages\nbclient\client.py", line 1305, in execute
    return NotebookClient(nb=nb, resources=resources, km=km, **kwargs).execute()
  File "C:\Users\jca92\.conda\envs\mem680\lib\site-packages\jupyter_core\utils\__init__.py", line 166, in wrapped
    return loop.run_until_complete(inner)
  File "C:\Users\jca92\.conda\envs\mem680\lib\asyncio\base_events.py", line 641, in run_until_complete
    return future.result()
  File "C:\Users\jca92\.conda\envs\mem680\lib\site-packages\nbclient\client.py", line 705, in async_execute
    await self.async_execute_cell(
  File "C:\Users\jca92\.conda\envs\mem680\lib\site-packages\nbclient\client.py", line 1058, in async_execute_cell
    await self._check_raise_for_error(cell, cell_index, exec_reply)
  File "C:\Users\jca92\.conda\envs\mem680\lib\site-packages\nbclient\client.py", line 914, in _check_raise_for_error
    raise CellExecutionError.from_cell_and_msg(cell, exec_reply_content)
nbclient.exceptions.CellExecutionError: An error occurred while executing the following cell:
------------------
cluster.DBSCAN()
cluster.lsfklsd
cluster.lsdfjdk


------------------


[1;31m---------------------------------------------------------------------------[0m
[1;31mNameError[0m                                 Traceback (most recent call last)
Input [1;32mIn [3][0m, in [0;36m<cell line: 1>[1;34m()[0m
[1;32m----> 1[0m [43mcluster[49m[38;5;241m.[39mDBSCAN()
[0;32m      2[0m cluster[38;5;241m.[39mlsfklsd
[0;32m      3[0m cluster[38;5;241m.[39mlsdfjdk

[1;31mNameError[0m: name 'cluster' is not defined

